# 错误、调试和测试
在程序运行过程中，总会遇到各种各样的错误。有的错误是程序编写有问题造成的，比如本来应该输出整数结果输出了字符串，这种错误我们通常称之为bug，bug是必须修复的。有的错误是用户输入造成的，比如让用户输入email地址，结果得到一个空字符串，这种错误可以通过检查用户输入来做相应的处理。还有一类错误是完全无法在程序运行过程中预测的，比如写入文件的时候，磁盘满了，写不进去了，或者从网络抓取数据，网络突然断掉了。这类错误也称为异常，在程序中通常是必须处理的，否则，程序会因为各种问题终止并退出。Python内置了一套异常处理机制，来帮助我们进行错误处理。此外，我们也需要跟踪程序的执行，查看变量的值是否正确，这个过程称为调试。Python的pdb可以让我们以单步方式执行代码。最后，编写测试也很重要。有了良好的测试，就可以在程序修改后反复运行，确保程序输出符合我们编写的测试。

## 错误处理
在程序运行的过程中，如果发生了错误，可以事先约定返回一个错误代码，这样，就可以知道是否有错，以及出错的原因。在操作系统提供的调用中，返回错误码非常常见。比如打开文件的函数open()，成功时返回文件描述符（就是一个整数），出错时返回-1。

用错误码来表示是否出错十分不便，因为函数本身应该返回的正常结果和错误码混在一起，造成调用者必须用大量的代码来判断是否出错：
```python
def foo():
    r = some_function()
    if r==(-1):
        return (-1)
    # do something
    return r

def bar():
    r = foo()
    if r==(-1):
        print('Error')
    else:
        pass
```
一旦出错，还要一级一级上报，直到某个函数可以处理该错误（比如，给用户输出一个错误信息）。

所以高级语言通常都内置了一套try...except...finally...的错误处理机制，Python也不例外。

### try
让我们用一个例子来看看try的机制：
```python
try:
    print('try...')
    r = 10 / 0
    print('result:', r)
except ZeroDivisionError as e:
    print('except:', e)
finally:
    print('finally...')
print('END')
```
当我们认为某些代码可能会出错时，就可以用try来运行这段代码，如果执行出错，则后续代码不会继续执行，而是直接跳转至错误处理代码，即except语句块，执行完except后，如果有finally语句块，则执行finally语句块，至此，执行完毕。

上面的代码在计算10 / 0时会产生一个除法运算错误：
```
try...
except: division by zero
finally...
END
```
从输出可以看到，当错误发生时，后续语句print('result:', r)不会被执行，except由于捕获到ZeroDivisionError，因此被执行。最后，finally语句被执行。然后，程序继续按照流程往下走。

如果把除数0改成2，则执行结果如下：
```
try...
result: 5
finally...
END
```
由于没有错误发生，所以except语句块不会被执行，但是finally如果有，则一定会被执行（可以没有finally语句）。

你还可以猜测，错误应该有很多种类，如果发生了不同类型的错误，应该由不同的except语句块处理。没错，可以有多个except来捕获不同类型的错误：
```python
try:
    print('try...')
    r = 10 / int('a')
    print('result:', r)
except ValueError as e:
    print('ValueError:', e)
except ZeroDivisionError as e:
    print('ZeroDivisionError:', e)
finally:
    print('finally...')
print('END')
```
int()函数可能会抛出ValueError，所以我们用一个except捕获ValueError，用另一个except捕获ZeroDivisionError。

此外，如果没有错误发生，可以在except语句块后面加一个else，当没有错误发生时，会自动执行else语句：
```python
try:
    print('try...')
    r = 10 / int('2')
    print('result:', r)
except ValueError as e:
    print('ValueError:', e)
except ZeroDivisionError as e:
    print('ZeroDivisionError:', e)
else:
    print('no error!')
finally:
    print('finally...')
print('END')
```

Python的错误其实也是class，所有的错误类型都继承自BaseException，所以在使用except时需要注意的是，它不但捕获该类型的错误，还把其子类也“一网打尽”。比如：
```python
try:
    foo()
except ValueError as e:
    print('ValueError')
except UnicodeError as e:
    print('UnicodeError')
```
第二个except永远也捕获不到UnicodeError，因为UnicodeError是ValueError的子类，如果有，也被第一个except给捕获了。

Python所有的错误都是从BaseException类派生的，常见的错误类型和继承关系看这里：
[`exception-hierarchy`](https://docs.python.org/3/library/exceptions.html#exception-hierarchy)

使用try...except捕获错误还有一个巨大的好处，就是可以跨越多层调用，比如函数main()调用foo()，foo()调用bar()，结果bar()出错了，这时，只要main()捕获到了，就可以处理：
```python
def foo(s):
    return 10 / int(s)

def bar(s):
    return foo(s) * 2

def main():
    try:
        bar('0')
    except Exception as e:
        print('Error:', e)
    finally:
        print('finally...')
```
也就是说，不需要在每个可能出错的地方去捕获错误，只要在合适的层次去捕获错误就可以了。这样一来，就大大减少了写try...except...finally的麻烦。

### 调用堆栈
如果错误没有被捕获，它就会一直往上抛，最后被Python解释器捕获，打印一个错误信息，然后程序退出。来看看err.py：
```python
# err.py:
def foo(s):
    return 10 / int(s)

def bar(s):
    return foo(s) * 2

def main():
    bar('0')

main()
```
打印信息如下：
```
Traceback (most recent call last):
  File "err.py", line 11, in <module>
    main()
  File "err.py", line 9, in main
    bar('0')
  File "err.py", line 6, in bar
    return foo(s) * 2
  File "err.py", line 3, in foo
    return 10 / int(s)
ZeroDivisionError: division by zero
```

### 记录错误
捕获异常，然后把错误堆栈打印出来，同时让程序继续。使用`logging`模块可以非常容易地记录错误信息：
```python
# err_logging.py

import logging

def foo(s):
    return 10 / int(s)

def bar(s):
    return foo(s) * 2

def main():
    try:
        bar('0')
    except Exception as e:
        logging.exception(e)

main()
print('END')
```
通过配置，logging还可以把错误记录到日志文件里，方便事后排查。

### 抛出错误
因为错误是class，捕获一个错误就是捕获到该class的一个实例。因此，错误并不是凭空产生的，而是有意创建并抛出的。Python的内置函数会抛出很多类型的错误，我们自己编写的函数也可以抛出错误。

如果要抛出错误，首先根据需要，可以定义一个错误的class，选择好继承关系，然后，用raise语句抛出一个错误的实例：
```python
# err_raise.py
class FooError(ValueError):
    pass

def foo(s):
    n = int(s)
    if n==0:
        raise FooError('invalid value: %s' % s)
    return 10 / n

foo('0')
```
执行，可以最后跟踪到我们自己定义的错误：
```
$ python3 err_raise.py 
Traceback (most recent call last):
  File "err_throw.py", line 11, in <module>
    foo('0')
  File "err_throw.py", line 8, in foo
    raise FooError('invalid value: %s' % s)
__main__.FooError: invalid value: 0
```
只有在必要的时候才定义我们自己的错误类型。如果可以选择Python已有的内置的错误类型（比如ValueError，TypeError），尽量使用Python内置的错误类型。

最后，我们来看另一种错误处理的方式：
```python
# err_reraise.py

def foo(s):
    n = int(s)
    if n==0:
        raise ValueError('invalid value: %s' % s)
    return 10 / n

def bar():
    try:
        foo('0')
    except ValueError as e:
        print('ValueError!')
        raise

bar()
```
在bar()函数中，我们明明已经捕获了错误，但是，打印一个ValueError!后，又把错误通过raise语句抛出去了，这不有病么？

其实这种错误处理方式不但没病，而且相当常见。捕获错误目的只是记录一下，便于后续追踪。但是，由于当前函数不知道应该怎么处理该错误，所以，最恰当的方式是继续往上抛，让顶层调用者去处理。好比一个员工处理不了一个问题时，就把问题抛给他的老板，如果他的老板也处理不了，就一直往上抛，最终会抛给CEO去处理。

raise语句如果不带参数，就会把当前错误原样抛出。此外，在except中raise一个Error，还可以把一种类型的错误转化成另一种类型：
```python
try:
    10 / 0
except ZeroDivisionError:
    raise ValueError('input error!')
```
只要是合理的转换逻辑就可以，但是，决不应该把一个IOError转换成毫不相干的ValueError。

### 小结
Python内置的`try...except...finally`用来处理错误十分方便。出错时，会分析错误信息并定位错误发生的代码位置才是最关键的。

程序也可以主动抛出错误，让调用者来处理相应的错误。但是，应该在文档中写清楚可能会抛出哪些错误，以及错误产生的原因。
## 调试
程序能一次写完并正常运行的概率很小，基本不超过1%。总会有各种各样的bug需要修正。有的bug很简单，看看错误信息就知道，有的bug很复杂，我们需要知道出错时，哪些变量的值是正确的，哪些变量的值是错误的，因此，需要一整套调试程序的手段来修复bug。

第一种方法简单直接粗暴有效，就是用print()把可能有问题的变量打印出来看看：
```python
def foo(s):
    n = int(s)
    print('>>> n = %d' % n)
    return 10 / n

def main():
    foo('0')

main()
```
执行后在输出中查找打印的变量值：
```
$ python3 err.py
>>> n = 0
Traceback (most recent call last):
  ...
ZeroDivisionError: integer division or modulo by zero
```
用print()最大的坏处是将来还得删掉它，想想程序里到处都是print()，运行结果也会包含很多垃圾信息。所以，我们又有第二种方法。

### 断言
凡是用print()来辅助查看的地方，都可以用断言（assert）来替代：
```python
def foo(s):
    n = int(s)
    assert n != 0, 'n is zero!'
    return 10 / n

def main():
    foo('0')
```
assert的意思是，表达式n != 0应该是True，否则，根据程序运行的逻辑，后面的代码肯定会出错。

如果断言失败，assert语句本身就会抛出AssertionError：
```
$ python3 err.py
Traceback (most recent call last):
  ...
AssertionError: n is zero!
```
程序中如果到处充斥着assert，和print()相比也好不到哪去。不过，启动Python解释器时可以用`-O`参数来关闭assert：
```
$ python3 -O err.py
Traceback (most recent call last):
  ...
ZeroDivisionError: division by zero
```

关闭后，你可以把所有的assert语句当成pass来看。
```
$ python3 -O err.py
Traceback (most recent call last):
  ...
ZeroDivisionError: division by zero
```

### logging
把print()替换为logging是第3种方式，和assert比，logging不会抛出错误，而且可以输出到文件：
```python
import logging
logging.basicConfig(level=logging.INFO)

n = 0
logging.info('n = %d' % n)
print(10 / n)
```
这就是logging的好处，它允许你指定记录信息的级别，有debug，info，warning，error等几个级别，当我们指定level=INFO时，logging.debug就不起作用了。同理，指定level=WARNING后，debug和info就不起作用了。这样一来，你可以放心地输出不同级别的信息，也不用删除，最后统一控制输出哪个级别的信息。

logging的另一个好处是通过简单的配置，一条语句可以同时输出到不同的地方，比如console和文件。

### pdb

`python -m pdb err.py`

第4种方式是启动Python的调试器pdb，让程序以单步方式运行，可以随时查看运行状态。我们先准备好程序：
```python
# err.py
s = '0'
n = int(s)
print(10 / n)
```
然后启动：
```
$ python3 -m pdb err.py
> /Users/michael/Github/learn-python3/samples/debug/err.py(2)<module>()
-> s = '0'
```

### IDE
如果要比较爽地设置断点、单步执行，就需要一个支持调试功能的IDE。目前比较好的Python IDE有[PyCharm](http://www.jetbrains.com/pycharm/)，Eclipse插件Pydev。

### 小结
写程序最痛苦的事情莫过于调试，程序往往会以你意想不到的流程来运行，你期待执行的语句其实根本没有执行，这时候，就需要调试了。

虽然用IDE调试起来比较方便，但是最后你会发现，logging才是终极武器。

## 单元测试
单元测试

如果你听说过“测试驱动开发”（TDD：Test-Driven Development），单元测试就不陌生。 单元测试是用来对一个模块、一个函数或者一个类来进行正确性检验的测试工作。 比如对函数abs()，我们可以编写出以下几个测试用例：

1. 输入正数，比如1、1.2、0.99，期待返回值与输入相同；
2. 输入负数，比如-1、-1.2、-0.99，期待返回值与输入相反；
3. 输入0，期待返回0；
4. 输入非数值类型，比如None、[]、{}，期待抛出TypeError。

把上面的测试用例放到一个测试模块里，就是一个完整的单元测试。如果单元测试通过，说明我们测试的这个函数能够正常工作。如果单元测试不通过，要么函数有bug，要么测试条件输入不正确，总之，需要修复使单元测试能够通过。 单元测试通过后有什么意义呢？如果我们对abs()函数代码做了修改，只需要再跑一遍单元测试，如果通过，说明我们的修改不会对abs()函数原有的行为造成影响，如果测试不通过，说明我们的修改与原有行为不一致，要么修改代码，要么修改测试。 这种以测试为驱动的开发模式最大的好处就是确保一个程序模块的行为符合我们设计的测试用例。在将来修改的时候，可以极大程度地保证该模块行为仍然是正确的。 我们来编写一个Dict类，这个类的行为和dict一致，但是可以通过属性来访问，用起来就像下面这样：
```python
>>> d = Dict(a=1, b=2)
>>> d['a']
1
>>> d.a
1
```
mydict.py代码如下：
```python
class Dict(dict):

    def __init__(self, **kw):
        super().__init__(**kw)

    def __getattr__(self, key):
        try:
            return self[key]
        except KeyError:
            raise AttributeError(r"'Dict' object has no attribute '%s'" % key)

    def __setattr__(self, key, value):
        self[key] = value
```

为了编写单元测试，我们需要引入Python自带的unittest模块，编写mydict_test.py如下：
```python
import unittest

from mydict import Dict

class TestDict(unittest.TestCase):

    def test_init(self):
        d = Dict(a=1, b='test')
        self.assertEqual(d.a, 1)
        self.assertEqual(d.b, 'test')
        self.assertTrue(isinstance(d, dict))

    def test_key(self):
        d = Dict()
        d['key'] = 'value'
        self.assertEqual(d.key, 'value')

    def test_attr(self):
        d = Dict()
        d.key = 'value'
        self.assertTrue('key' in d)
        self.assertEqual(d['key'], 'value')

    def test_keyerror(self):
        d = Dict()
        with self.assertRaises(KeyError):
            value = d['empty']

    def test_attrerror(self):
        d = Dict()
        with self.assertRaises(AttributeError):
            value = d.empty
```

编写单元测试时，我们需要编写一个测试类，从unittest.TestCase继承。 以test开头的方法就是测试方法，不以test开头的方法不被认为是测试方法，测试的时候不会被执行。

对每一类测试都需要编写一个test_xxx()方法。由于unittest.TestCase提供了很多内置的条件判断，我们只需要调用这些方法就可以断言输出是否是我们所期望的。最常用的断言就是assertEqual()。

### 运行单元测试
使用函数运行
```python
if __name__ == '__main__':
    unittest.main()
```

使用`-m`参数运行
```bash
python3 -m unittest mydict_test
```
这是推荐的做法，因为这样可以一次批量运行很多单元测试，并且，有很多工具可以自动来运行这些单元测试。

### setUp与tearDown
可以在单元测试中编写两个特殊的setUp()和tearDown()方法。这两个方法会分别在每调用一个测试方法的前后分别被执行。

setUp()和tearDown()方法有什么用呢？设想你的测试需要启动一个数据库，这时，就可以在setUp()方法中连接数据库，在tearDown()方法中关闭数据库，这样，不必在每个测试方法中重复相同的代码：
```python
class TestDict(unittest.TestCase):

    def setUp(self):
        print('setUp...')

    def tearDown(self):
        print('tearDown...')
```
可以再次运行测试看看每个测试方法调用前后是否会打印出setUp...和tearDown...。

### 小结
单元测试可以有效地测试某个程序模块的行为，是未来重构代码的信心保证。

单元测试的测试用例要覆盖常用的输入组合、边界条件和异常。

单元测试代码要非常简单，如果测试代码太复杂，那么测试代码本身就可能有bug。

单元测试通过了并不意味着程序就没有bug了，但是不通过程序肯定有bug。

